Workbook
Name ListaDevs: #REF!

Sheet Devs
A1: ID | B1: Nickname | C1: Domain | D1: Ecosystem | E1: Language | F1: summary_of_common_team_projects
A2: 5 | B2: Dev5 | C2: Mobile | D2: Android | E2: Kotlin | F2: 5-263: P179(,osf=0.489,slf=0.711) | 5-468: P82(,osf=0.567,slf=0.737) | 5-503: P145(,osf=0.612,slf=0.871); P177(,osf=0.340,slf=0.621); P213(,osf=0.312,slf=0.608); P216(,osf=0.401,slf=0.341); P279(,osf=0.594,slf=0.422)
A3: 7 | B3: Dev7 | C3: Web | D3: React | E3: JavaScript | F3: 7-193: P82(,osf=0.567,slf=0.737); P85(,osf=0.784,slf=0.538) | 7-194: P40(,osf=0.733,slf=0.373); P82(,osf=0.567,slf=0.737); P85(,osf=0.784,slf=0.538)
A4: 8 | B4: Dev8 | C4: IoT | F4: 8-142: P104(,osf=0.636,slf=0.624); P175(,osf=0.716,slf=0.339); P205(,osf=0.588,slf=0.465); P92(,osf=0.849,slf=0.891) | 8-290: P175(,osf=0.716,slf=0.339); P205(,osf=0.588,slf=0.465); P92(,osf=0.849,slf=0.891)
A5: 27 | B5: Dev27 | C5: Web | E5: JavaScript | F5: 27-363: P103(,osf=0.739,slf=0.847); P123(,osf=0.393,slf=0.825); P144(,osf=0.541,slf=0.688); P145(,osf=0.612,slf=0.871); P148(,osf=0.411,slf=0.639); P149(,osf=0.325,slf=0.603); P150(,osf=0.475,slf=0.317); P171(,osf=0.486,slf=0.531); P177(,osf=0.340,slf=0.621); P179(,osf=0.489,slf=0.711); P239(,osf=0.422,slf=0.462); P240(,osf=0.385,slf=0.409); P258(,osf=0.666,slf=0.352); P72(,osf=0.639,slf=0.456); P80(,osf=0.559,slf=0.624); P82(,osf=0.567,slf=0.737); P85(,osf=0.784,slf=0.538); P99(,osf=0.757,slf=0.452)
A6: 29 | B6: Dev29 | C6: Web | D6: Vue | E6: JavaScript | F6: 29-524: P106(,osf=0.303,slf=0.349); P262(,osf=0.819,slf=0.404)
A7: 33 | B7: Dev33 | D7: Android, CouchDB, iOS/iPadOS | E7: JavaScript
A8: 36 | B8: Dev36 | C8: Mobile | D8: Android | E8: Kotlin | F8: 36-181: P82(,osf=0.567,slf=0.737)
A9: 38 | B9: Dev38 | C9: Web | D9: iOS/iPadOS | F9: 38-225: P82(,osf=0.567,slf=0.737)
A10: 62 | B10: Dev62 | D10: MongoDB, iOS/iPadOS | F10: 62-415: P85(,osf=0.784,slf=0.538)
A11: 71 | B11: Dev71 | C11: IoT, Web | D11: iOS/iPadOS | E11: HTML, JavaScript, Python
A12: 81 | B12: Dev81 | C12: IoT | E12: JavaScript | F12: 81-104: P69(,osf=0.478,slf=0.301)
A13: 93 | B13: Dev93 | C13: Desktop | D13: .NET | E13: C# | F13: 93-270: P82(,osf=0.567,slf=0.737) | 93-292: P82(,osf=0.567,slf=0.737) | 93-437: P158(,osf=0.670,slf=0.322); P82(,osf=0.567,slf=0.737); P85(,osf=0.784,slf=0.538)
A14: 103 | B14: Dev103 | C14: Web | D14: Angular | E14: TypeScript | F14: 103-544: P82(,osf=0.567,slf=0.737); P85(,osf=0.784,slf=0.538)
A15: 104 | B15: Dev104 | C15: Mobile | D15: Android | E15: Kotlin | F15: 104-81: P69(,osf=0.478,slf=0.301)
A16: 115 | B16: Dev115 | C16: Web | D16: Node.js | E16: JavaScript
A17: 119 | B17: Dev119 | C17: Mobile | D17: iOS/iPadOS | E17: Swift | F17: 119-193: P82(,osf=0.567,slf=0.737) | 119-399: P82(,osf=0.567,slf=0.737)
A18: 142 | B18: Dev142 | C18: Mobile | D18: Android | E18: Kotlin | F18: 142-8: P104(,osf=0.636,slf=0.624); P175(,osf=0.716,slf=0.339); P205(,osf=0.588,slf=0.465); P92(,osf=0.849,slf=0.891) | 142-290: P175(,osf=0.716,slf=0.339); P205(,osf=0.588,slf=0.465); P242(,osf=0.558,slf=0.665); P253(,osf=0.540,slf=0.837); P71(,osf=0.523,slf=0.674); P79(,osf=0.323,slf=0.442); P82(,osf=0.567,slf=0.737); P85(,osf=0.784,slf=0.538); P92(,osf=0.849,slf=0.891)
A19: 143 | B19: Dev143 | C19: Cloud | D19: AWS Lambda | E19: Python | F19: 143-370: P68(,osf=0.644,slf=0.857)
A20: 145 | B20: Dev145 | C20: IoT, Web | D20: iOS/iPadOS | E20: JSON, JavaScript | F20: 145-263: P179(,osf=0.489,slf=0.711); P201(,osf=0.535,slf=0.596)
A21: 154 | B21: Dev154 | C21: Cloud | D21: AWS Lambda | E21: Python
A22: 169 | B22: Dev169 | C22: Web | D22: React | E22: JavaScript
A23: 174 | B23: Dev174 | C23: Web | D23: Vue | E23: JavaScript
A24: 181 | B24: Dev181 | C24: Cloud | D24: AWS Lambda | E24: Python | F24: 181-36: P82(,osf=0.567,slf=0.737)
A25: 193 | B25: Dev193 | C25: Web | D25: Spring Boot | E25: Java | F25: 193-7: P82(,osf=0.567,slf=0.737); P85(,osf=0.784,slf=0.538) | 193-119: P82(,osf=0.567,slf=0.737) | 193-194: P82(,osf=0.567,slf=0.737); P85(,osf=0.784,slf=0.538) | 193-399: P82(,osf=0.567,slf=0.737); P85(,osf=0.784,slf=0.538)
A26: 194 | B26: Dev194 | C26: Mobile | D26: Android | E26: Kotlin | F26: 194-7: P40(,osf=0.733,slf=0.373); P82(,osf=0.567,slf=0.737); P85(,osf=0.784,slf=0.538) | 194-193: P82(,osf=0.567,slf=0.737); P85(,osf=0.784,slf=0.538)
A27: 198 | B27: Dev198 | C27: Web | D27: Vue | E27: JavaScript | F27: 198-415: P82(,osf=0.567,slf=0.737)
A28: 205 | B28: Dev205 | C28: Mobile | D28: Android | E28: Kotlin | F28: 205-526: P139(,osf=0.325,slf=0.436)
A29: 209 | B29: Dev209 | C29: Web | D29: Node.js | E29: JavaScript
A30: 225 | B30: Dev225 | C30: Web | D30: React | E30: JavaScript | F30: 225-38: P82(,osf=0.567,slf=0.737)
A31: 241 | B31: Dev241 | C31: Web | D31: Node.js | E31: JavaScript
A32: 250 | B32: Dev250 | C32: Cloud | D32: AWS Lambda | E32: Python
A33: 263 | B33: Dev263 | C33: Web | D33: Vue | E33: JavaScript | F33: 263-5: P179(,osf=0.489,slf=0.711) | 263-145: P179(,osf=0.489,slf=0.711); P201(,osf=0.535,slf=0.596)
A34: 265 | B34: Dev265 | C34: Web | D34: Spring Boot | E34: Java
A35: 270 | B35: Dev270 | C35: Web | D35: Angular | E35: TypeScript | F35: 270-93: P82(,osf=0.567,slf=0.737) | 270-411: P82(,osf=0.567,slf=0.737) | 270-438: P82(,osf=0.567,slf=0.737)
A36: 283 | B36: Dev283 | C36: Web | D36: Vue | E36: JavaScript
A37: 290 | B37: Dev290 | C37: Web | D37: Vue | E37: JavaScript | F37: 290-8: P175(,osf=0.716,slf=0.339); P205(,osf=0.588,slf=0.465); P92(,osf=0.849,slf=0.891) | 290-142: P175(,osf=0.716,slf=0.339); P205(,osf=0.588,slf=0.465); P242(,osf=0.558,slf=0.665); P253(,osf=0.540,slf=0.837); P71(,osf=0.523,slf=0.674); P79(,osf=0.323,slf=0.442); P82(,osf=0.567,slf=0.737); P85(,osf=0.784,slf=0.538); P92(,osf=0.849,slf=0.891)
A38: 292 | B38: Dev292 | C38: Web | D38: Node.js | E38: JavaScript | F38: 292-93: P82(,osf=0.567,slf=0.737) | 292-437: P82(,osf=0.567,slf=0.737)
A39: 293 | B39: Dev293 | C39: Web | D39: Angular | E39: TypeScript | F39: 293-438: P124(,osf=0.678,slf=0.507); P152(,osf=0.337,slf=0.880)
A40: 297 | B40: Dev297 | C40: Web | D40: Node.js | E40: JavaScript
...

Sheet Projects
A1: Project ID | B1: Name | C1: Description | D1: Domain_must | E1: Domain_should | F1: Domain_could | G1: Ecosystem_must | H1: Ecosystem_should | I1: Ecosystem_could | J1: Language_must | K1: Language_should | L1: Language_could
A2: P_ | B2: <nome_do_projeto>
A3: P1 | B3: .NET Corporate Portal Maintainance | C3: Internal corporate portal in .NET, with both desktop and web components, critical for administrative routines. Objective: fix bugs, improve performance, and gradually modernize the front-end without disrupting operations. | D3: Desktop, Web | E3: Cloud | F3: Mobile | G3: .NET | H3: React | I3: MongoDB | J3: C# | K3: JavaScript, TypeScript | L3: Python
A4: P2 | B4: Hybrid Mobile App with Web Panel | C4: Mobile application for Android and iOS consuming an existing backend, with a simple web panel for support. Focus on UX, good cross-platform communication, and stable backend integration. | D4: Mobile | E4: Web | F4: Cloud | G4: Android, iOS/iPadOS | H4: React | I4: .NET | J4: Kotlin, Swift | K4: JavaScript, TypeScript | L4: Java, C#
A5: P3 | B5: Cloud IoT Sensor Platform | C5: Platform to collect IoT sensor data, process it in the cloud, and display it on a web dashboard. Focus on robust data ingestion, cloud processing, and minimal but functional visualization. | D5: IoT, Cloud | E5: Web | F5: Desktop | G5: AWS Lambda | H5: React, Angular, MongoDB | I5: Android | J5: Python, C++ | K5: JavaScript | L5: Java, TypeScript
A6: P4 | B6: Web Analytic Reports SaaS | C6: Web-based SaaS application for generating dashboards and analytical reports using MongoDB data. Emphasis on efficient queries, solid data modeling, and a clear visualization interface. | D6: Web | E6: Cloud | F6: Desktop | G6: MongoDB | H6: Angular, React | I6: AWS Lambda | J6: JavaScript | K6: TypeScript, Python | L6: Java, C#
A7: P5 | B7: Critical Web + Cloud Platform | C7: Mission-critical Web + Cloud system with a React front-end, serverless backend on AWS Lambda, and MongoDB database. Requires high reliability, testing, monitoring, and scalability. | D7: Web, Cloud | E7: Mobile | F7: Desktop | G7: React, AWS Lambda, MongoDB | H7: .NET | I7: Android | J7: JavaScript, TypeScript, Python | K7: C#, Java | L7: Kotlin, Swift
A8: P6 | B8: Critical Embedded Hardware Platform | C8: Development of an electronic board (PCB) and embedded firmware for a mission-critical device. Includes board design, prototyping, bring-up, drivers, sensor reading/actuator control, bench testing, and validation. | D8: Hardware, Embedded | E8: IoT | F8: Cloud | G8: PCB, Desenvolvimento de Placa | H8: Eletrônica (circuitos lógicos e analógicos) | I8: Instrumentação (osciloscópio, analisador lógico), Prototipação | J8: C | K8: C++ (se tiver firmware mais complexo) | L8: Python (scripts de teste/automação de bancada)

Sheet Ranking_Expert
A1: Project ID | B1: Requirements | C1: Team ID | D1: Dev1 | E1: Dev2 | F1: Dev3 | G1: Dev4 | H1: Rank expert | I1: team_match_summary | J1: DOM_M | K1: DOM_S | L1: DOM_C | M1: ECO_M | N1: ECO_S | O1: ECO_C | P1: LING_M | Q1: LING_S | R1: LING_C | S1: MUST_OK | T1: TOTAL_ABSENCES_MUST | U1: note_dev1 | V1: note_dev2 | W1: note_dev3 | X1: note_dev4
A2: P1 | B2: =IFERROR(VLOOKUP(A2,Projects!$A$2:$C$7,2,FALSE),"") -> .NET Corporate Portal Maintainance | C2: P1-TEAM1 | D2: Dev169 | E2: Dev27 | F2: Dev81 | G2: Dev363 | H2: 3 | I2: DOM M(1/2)[web] S(0/1)[] C(1/1)[mobile] | ECO M(0/1)[] S(1/1)[react] C(0/1)[] | LING M(0/1)[] S(1/2)[javascript] C(0/1)[] | J2: =IFERROR(__xludf.DUMMYFUNCTION("IFERROR(REGEXEXTRACT($I2,""DOM\s*M\((\d+/\d+)\)""),"""") "),"1/2") -> 1/2 | K2: =IFERROR(__xludf.DUMMYFUNCTION("IFERROR(REGEXEXTRACT($I2,""DOM.*?S\((\d+/\d+)\)""),"""") "),"0/1") -> 0/1 | L2: =IFERROR(__xludf.DUMMYFUNCTION("IFERROR(REGEXEXTRACT($I2,""DOM.*?C\((\d+/\d+)\)""),"""") "),"1/1") -> 1/1 | M2: =IFERROR(__xludf.DUMMYFUNCTION("IFERROR(REGEXEXTRACT($I2,""ECO\s*M\((\d+/\d+)\)""),"""") "),"0/1") -> 0/1 | N2: =IFERROR(__xludf.DUMMYFUNCTION("IFERROR(REGEXEXTRACT($I2,""ECO.*?S\((\d+/\d+)\)""),"""") "),"1/1") -> 1/1 | O2: =IFERROR(__xludf.DUMMYFUNCTION("IFERROR(REGEXEXTRACT($I2,""ECO.*?C\((\d+/\d+)\)""),"""") "),"0/1") -> 0/1 | P2: =IFERROR(__xludf.DUMMYFUNCTION("IFERROR(REGEXEXTRACT($I2,""LING\s*M\((\d+/\d+)\)""),"""") "),"0/1") -> 0/1 | Q2: =IFERROR(__xludf.DUMMYFUNCTION("IFERROR(REGEXEXTRACT($I2,""LING.*?S\((\d+/\d+)\)""),"""") "),"1/2") -> 1/2 | R2: =IFERROR(__xludf.DUMMYFUNCTION("IFERROR(REGEXEXTRACT($I2,""LING[^|]*C\(([0-9]+/[0-9]+)\)""),"""") "),"0/1") -> 0/1 | S2: =IFERROR(__xludf.DUMMYFUNCTION("AND( VALUE(INDEX(SPLIT(J2,""/""),1))=VALUE(INDEX(SPLIT(J2,""/""),2)), VALUE(INDEX(SPLIT(M2,""/""),1))=VALUE(INDEX(SPLIT(M2,""/""),2)), VALUE(INDEX(SPLIT(P2,""/""),1))=VALUE(INDEX(SPLIT(P2,""/""),2)) ) "),FALSE) -> FALSE | T2: =IFERROR(__xludf.DUMMYFUNCTION(" (VALUE(INDEX(SPLIT(J2,""/""),2))-VALUE(INDEX(SPLIT(J2,""/""),1))) + (VALUE(INDEX(SPLIT(M2,""/""),2))-VALUE(INDEX(SPLIT(M2,""/""),1))) + (VALUE(INDEX(SPLIT(P2,""/""),2))-VALUE(INDEX(SPLIT(P2,""/""),1))) "),3.0) -> 3 | U2: Domain: Web Ecosystem: React Language: JavaScript Match: DOM: M (1/2)[web] S (0/1)[] C (0/1)[] ECO: M (0/1)[] S (1/1)[react] C (0/1)[] LING: M (0/1)[] S (1/2)[javascript] C (0/1)[] Collaboration:: 169-27: UNCOMMON 169-81: UNCOMMON 169-363: UNCOMMON | V2: Domain: Web Ecosystem: nan Language: JavaScript Match: DOM: M (1/2)[web] S (0/1)[] C (0/1)[] ECO: M (0/1)[] S (0/1)[] C (0/1)[] LING: M (0/1)[] S (1/2)[javascript] C (0/1)[] Collaboration:: 27-81: UNCOMMON 27-169: UNCOMMON 27-363: P103(,osf=0.739,slf=0.847); P123(,osf=0.393,slf=0.825); P144(,osf=0.541,slf=0.688); P145(,osf=0.612,slf=0.871); P148(,osf=0.411,slf=0.639); P149(,osf=0.325,slf=0.603); P150(,osf=0.475,slf=0.317); P171(,osf=0.486,slf=0.531); P177(,osf=0.340,slf=0.621); P179(,osf=0.489,slf=0.711); P239(,osf=0.422,slf=0.462); P240(,osf=0.385,slf=0.409); P258(,osf=0.666,slf=0.352); P72(,osf=0.639,slf=0.456); P80(,osf=0.559,slf=0.624); P82(,osf=0.567,slf=0.737); P85(,osf=0.784,slf=0.538); P99(,osf=0.757,slf=0.452) | W2: Domain: IoT Ecosystem: nan Language: JavaScript Match: DOM: M (0/2)[] S (0/1)[] C (0/1)[] ECO: M (0/1)[] S (0/1)[] C (0/1)[] LING: M (0/1)[] S (1/2)[javascript] C (0/1)[] Collaboration:: 81-27: UNCOMMON 81-169: UNCOMMON 81-363: UNCOMMON | X2: Domain: Mobile Ecosystem: iOS/iPadOS Language: Swift Match: DOM: M (0/2)[] S (0/1)[] C (1/1)[mobile] ECO: M (0/1)[] S (0/1)[] C (0/1)[] LING: M (0/1)[] S (0/2)[] C (0/1)[] Collaboration:: 363-27: P103(,osf=0.739,slf=0.847); P123(,osf=0.393,slf=0.825); P144(,osf=0.541,slf=0.688); P145(,osf=0.612,slf=0.871); P148(,osf=0.411,slf=0.639); P149(,osf=0.325,slf=0.603); P150(,osf=0.475,slf=0.317); P171(,osf=0.486,slf=0.531); P177(,osf=0.340,slf=0.621); P179(,osf=0.489,slf=0.711); P239(,osf=0.422,slf=0.462); P240(,osf=0.385,slf=0.409); P258(,osf=0.666,slf=0.352); P72(,osf=0.639,slf=0.456); P80(,osf=0.559,slf=0.624); P82(,osf=0.567,slf=0.737); P85(,osf=0.784,slf=0.538); P99(,osf=0.757,slf=0.452) | 363-447: P123(,osf=0.393,slf=0.825); P144(,osf=0.541,slf=0.688); P145(,osf=0.612,slf=0.871); P148(,osf=0.411,slf=0.639); P149(,osf=0.325,slf=0.603); P150(,osf=0.475,slf=0.317); P171(,osf=0.486,slf=0.531); P177(,osf=0.340,slf=0.621); P179(,osf=0.489,slf=0.711); P214(,osf=0.335,slf=0.820); P239(,osf=0.422,slf=0.462); P240(,osf=0.385,slf=0.409); P258(,osf=0.666,slf=0.352); P82(,osf=0.567,slf=0.737); P85(,osf=0.784,slf=0.538) | 363-544: P123(,osf=0.393,slf=0.825); P144(,osf=0.541,slf=0.688); P145(,osf=0.612,slf=0.871); P148(,osf=0.411,slf=0.639); P149(,osf=0.325,slf=0.603); P150(,osf=0.475,slf=0.317); P171(,osf=0.486,slf=0.531); P177(,osf=0.340,slf=0.621); P179(,osf=0.489,slf=0.711); P239(,osf=0.422,slf=0.462); P240(,osf=0.385,slf=0.409); P258(,osf=0.666,slf=0.352); P82(,osf=0.567,slf=0.737); P85(,osf=0.784,slf=0.538) 363-81: UNCOMMON 363-169: UNCOMMON
B3: =IFERROR( "DOM M["&VLOOKUP($A2,Projects!$A:$L,4,FALSE)&"] S["&VLOOKUP($A2,Projects!$A:$L,5,FALSE)&"] C["&VLOOKUP($A2,Projects!$A:$L,6,FALSE)&"]"&CHAR(10)& "ECO M["&VLOOKUP($A2,Projects!$A:$L,7,FALSE)&"] S["&VLOOKUP($A2,Projects!$A:$L,8,FALSE)&"] C["&VLOOKUP($A2,Projects!$A:$L,9,FALSE)&"]"&CHAR(10)& "LING M["&VLOOKUP($A2,Projects!$A:$L,10,FALSE)&"] S["&VLOOKUP($A2,Projects!$A:$L,11,FALSE)&"] C["&VLOOKUP($A2,Projects!$A:$L,12,FALSE)&"]" ,"") -> DOM M[Desktop, Web] S[Cloud] C[Mobile] ECO M[.NET] S[React] C[MongoDB] LING M[C#] S[JavaScript, TypeScript] C[Python] | C3: P1-TEAM2 | D3: Dev71 | E3: Dev518 | F3: Dev509 | G3: Dev439 | H3: 4 | I3: DOM M(1/2)[web] S(0/1)[] C(0/1)[] | ECO M(0/1)[] S(1/1)[react] C(0/1)[] | LING M(0/1)[] S(2/2)[javascript, typescript] C(1/1)[python] | J3: =IFERROR(__xludf.DUMMYFUNCTION("IFERROR(REGEXEXTRACT($I3,""DOM\s*M\((\d+/\d+)\)""),"""") "),"1/2") -> 1/2 | K3: =IFERROR(__xludf.DUMMYFUNCTION("IFERROR(REGEXEXTRACT($I3,""DOM.*?S\((\d+/\d+)\)""),"""") "),"0/1") -> 0/1 | L3: =IFERROR(__xludf.DUMMYFUNCTION("IFERROR(REGEXEXTRACT($I3,""DOM.*?C\((\d+/\d+)\)""),"""") "),"0/1") -> 0/1 | M3: =IFERROR(__xludf.DUMMYFUNCTION("IFERROR(REGEXEXTRACT($I3,""ECO\s*M\((\d+/\d+)\)""),"""") "),"0/1") -> 0/1 | N3: =IFERROR(__xludf.DUMMYFUNCTION("IFERROR(REGEXEXTRACT($I3,""ECO.*?S\((\d+/\d+)\)""),"""") "),"1/1") -> 1/1 | O3: =IFERROR(__xludf.DUMMYFUNCTION("IFERROR(REGEXEXTRACT($I3,""ECO.*?C\((\d+/\d+)\)""),"""") "),"0/1") -> 0/1 | P3: =IFERROR(__xludf.DUMMYFUNCTION("IFERROR(REGEXEXTRACT($I3,""LING\s*M\((\d+/\d+)\)""),"""") "),"0/1") -> 0/1 | Q3: =IFERROR(__xludf.DUMMYFUNCTION("IFERROR(REGEXEXTRACT($I3,""LING.*?S\((\d+/\d+)\)""),"""") "),"2/2") -> 2/2 | R3: =IFERROR(__xludf.DUMMYFUNCTION("IFERROR(REGEXEXTRACT($I3,""LING[^|]*C\(([0-9]+/[0-9]+)\)""),"""") "),"1/1") -> 1/1 | S3: =IFERROR(__xludf.DUMMYFUNCTION("AND( VALUE(INDEX(SPLIT(J3,""/""),1))=VALUE(INDEX(SPLIT(J3,""/""),2)), VALUE(INDEX(SPLIT(M3,""/""),1))=VALUE(INDEX(SPLIT(M3,""/""),2)), VALUE(INDEX(SPLIT(P3,""/""),1))=VALUE(INDEX(SPLIT(P3,""/""),2)) ) "),FALSE) -> FALSE | T3: =IFERROR(__xludf.DUMMYFUNCTION(" (VALUE(INDEX(SPLIT(J3,""/""),2))-VALUE(INDEX(SPLIT(J3,""/""),1))) + (VALUE(INDEX(SPLIT(M3,""/""),2))-VALUE(INDEX(SPLIT(M3,""/""),1))) + (VALUE(INDEX(SPLIT(P3,""/""),2))-VALUE(INDEX(SPLIT(P3,""/""),1))) "),3.0) -> 3
C4: P1-TEAM3 | D4: Dev205 | E4: Dev526 | F4: Dev363 | G4: Dev447 | H4: 4 | I4: DOM M(1/2)[web] S(0/1)[] C(1/1)[mobile] | ECO M(0/1)[] S(1/1)[react] C(0/1)[] | LING M(0/1)[] S(1/2)[javascript] C(0/1)[] | J4: =IFERROR(__xludf.DUMMYFUNCTION("IFERROR(REGEXEXTRACT($I4,""DOM\s*M\((\d+/\d+)\)""),"""") "),"1/2") -> 1/2 | K4: =IFERROR(__xludf.DUMMYFUNCTION("IFERROR(REGEXEXTRACT($I4,""DOM.*?S\((\d+/\d+)\)""),"""") "),"0/1") -> 0/1 | L4: =IFERROR(__xludf.DUMMYFUNCTION("IFERROR(REGEXEXTRACT($I4,""DOM.*?C\((\d+/\d+)\)""),"""") "),"1/1") -> 1/1 | M4: =IFERROR(__xludf.DUMMYFUNCTION("IFERROR(REGEXEXTRACT($I4,""ECO\s*M\((\d+/\d+)\)""),"""") "),"0/1") -> 0/1 | N4: =IFERROR(__xludf.DUMMYFUNCTION("IFERROR(REGEXEXTRACT($I4,""ECO.*?S\((\d+/\d+)\)""),"""") "),"1/1") -> 1/1 | O4: =IFERROR(__xludf.DUMMYFUNCTION("IFERROR(REGEXEXTRACT($I4,""ECO.*?C\((\d+/\d+)\)""),"""") "),"0/1") -> 0/1 | P4: =IFERROR(__xludf.DUMMYFUNCTION("IFERROR(REGEXEXTRACT($I4,""LING\s*M\((\d+/\d+)\)""),"""") "),"0/1") -> 0/1 | Q4: =IFERROR(__xludf.DUMMYFUNCTION("IFERROR(REGEXEXTRACT($I4,""LING.*?S\((\d+/\d+)\)""),"""") "),"1/2") -> 1/2 | R4: =IFERROR(__xludf.DUMMYFUNCTION("IFERROR(REGEXEXTRACT($I4,""LING[^|]*C\(([0-9]+/[0-9]+)\)""),"""") "),"0/1") -> 0/1 | S4: =IFERROR(__xludf.DUMMYFUNCTION("AND( VALUE(INDEX(SPLIT(J4,""/""),1))=VALUE(INDEX(SPLIT(J4,""/""),2)), VALUE(INDEX(SPLIT(M4,""/""),1))=VALUE(INDEX(SPLIT(M4,""/""),2)), VALUE(INDEX(SPLIT(P4,""/""),1))=VALUE(INDEX(SPLIT(P4,""/""),2)) ) "),FALSE) -> FALSE | T4: =IFERROR(__xludf.DUMMYFUNCTION(" (VALUE(INDEX(SPLIT(J4,""/""),2))-VALUE(INDEX(SPLIT(J4,""/""),1))) + (VALUE(INDEX(SPLIT(M4,""/""),2))-VALUE(INDEX(SPLIT(M4,""/""),1))) + (VALUE(INDEX(SPLIT(P4,""/""),2))-VALUE(INDEX(SPLIT(P4,""/""),1))) "),3.0) -> 3 | U4: Domain: Mobile Ecosystem: Android Language: Kotlin Match: DOM: M (0/2)[] S (0/1)[] C (1/1)[mobile] ECO: M (0/1)[] S (0/1)[] C (0/1)[] LING: M (0/1)[] S (0/2)[] C (0/1)[] Collaboration:: 205-363: UNCOMMON 205-447: UNCOMMON 205-526: P139(,osf=0.325,slf=0.436) | V4: Domain: Web Ecosystem: React Language: JavaScript Match: DOM: M (1/2)[web] S (0/1)[] C (0/1)[] ECO: M (0/1)[] S (1/1)[react] C (0/1)[] LING: M (0/1)[] S (1/2)[javascript] C (0/1)[] Collaboration:: 526-205: P139(,osf=0.325,slf=0.436) 526-363: UNCOMMON 526-447: UNCOMMON | W4: Domain: Mobile Ecosystem: iOS/iPadOS Language: Swift Match: DOM: M (0/2)[] S (0/1)[] C (1/1)[mobile] ECO: M (0/1)[] S (0/1)[] C (0/1)[] LING: M (0/1)[] S (0/2)[] C (0/1)[] Collaboration:: 363-205: UNCOMMON 363-447: UNCOMMON 363-526: UNCOMMON | X4: Domain: Mobile Ecosystem: iOS/iPadOS Language: Swift Match: DOM: M (0/2)[] S (0/1)[] C (1/1)[mobile] ECO: M (0/1)[] S (0/1)[] C (0/1)[] LING: M (0/1)[] S (0/2)[] C (0/1)[] Collaboration:: 447-205: UNCOMMON 447-363: P123(,osf=0.393,slf=0.825); P144(,osf=0.541,slf=0.688); P145(,osf=0.612,slf=0.871); P148(,osf=0.411,slf=0.639); P149(,osf=0.325,slf=0.603); P150(,osf=0.475,slf=0.317); P171(,osf=0.486,slf=0.531); P177(,osf=0.340,slf=0.621); P179(,osf=0.489,slf=0.711); P214(,osf=0.335,slf=0.820); P239(,osf=0.422,slf=0.462); P240(,osf=0.385,slf=0.409); P258(,osf=0.666,slf=0.352); P82(,osf=0.567,slf=0.737); P85(,osf=0.784,slf=0.538) 447-526: UNCOMMON
C5: P1-TEAM4 | D5: Dev33 | E5: Dev303 | F5: Dev270 | G5: Dev93 | H5: 2 | I5: DOM M(2/2)[desktop, web] S(0/1)[] C(0/1)[] | ECO M(1/1)[.net] S(0/1)[] C(0/1)[] | LING M(1/1)[c#] S(2/2)[javascript, typescript] C(0/1)[] | J5: =IFERROR(__xludf.DUMMYFUNCTION("IFERROR(REGEXEXTRACT($I5,""DOM\s*M\((\d+/\d+)\)""),"""") "),"2/2") -> 2/2 | K5: =IFERROR(__xludf.DUMMYFUNCTION("IFERROR(REGEXEXTRACT($I5,""DOM.*?S\((\d+/\d+)\)""),"""") "),"0/1") -> 0/1 | L5: =IFERROR(__xludf.DUMMYFUNCTION("IFERROR(REGEXEXTRACT($I5,""DOM.*?C\((\d+/\d+)\)""),"""") "),"0/1") -> 0/1 | M5: =IFERROR(__xludf.DUMMYFUNCTION("IFERROR(REGEXEXTRACT($I5,""ECO\s*M\((\d+/\d+)\)""),"""") "),"1/1") -> 1/1 | N5: =IFERROR(__xludf.DUMMYFUNCTION("IFERROR(REGEXEXTRACT($I5,""ECO.*?S\((\d+/\d+)\)""),"""") "),"0/1") -> 0/1 | O5: =IFERROR(__xludf.DUMMYFUNCTION("IFERROR(REGEXEXTRACT($I5,""ECO.*?C\((\d+/\d+)\)""),"""") "),"0/1") -> 0/1 | P5: =IFERROR(__xludf.DUMMYFUNCTION("IFERROR(REGEXEXTRACT($I5,""LING\s*M\((\d+/\d+)\)""),"""") "),"1/1") -> 1/1 | Q5: =IFERROR(__xludf.DUMMYFUNCTION("IFERROR(REGEXEXTRACT($I5,""LING.*?S\((\d+/\d+)\)""),"""") "),"2/2") -> 2/2 | R5: =IFERROR(__xludf.DUMMYFUNCTION("IFERROR(REGEXEXTRACT($I5,""LING[^|]*C\(([0-9]+/[0-9]+)\)""),"""") "),"0/1") -> 0/1 | S5: =IFERROR(__xludf.DUMMYFUNCTION("AND( VALUE(INDEX(SPLIT(J5,""/""),1))=VALUE(INDEX(SPLIT(J5,""/""),2)), VALUE(INDEX(SPLIT(M5,""/""),1))=VALUE(INDEX(SPLIT(M5,""/""),2)), VALUE(INDEX(SPLIT(P5,""/""),1))=VALUE(INDEX(SPLIT(P5,""/""),2)) ) "),TRUE) -> TRUE | T5: =IFERROR(__xludf.DUMMYFUNCTION(" (VALUE(INDEX(SPLIT(J5,""/""),2))-VALUE(INDEX(SPLIT(J5,""/""),1))) + (VALUE(INDEX(SPLIT(M5,""/""),2))-VALUE(INDEX(SPLIT(M5,""/""),1))) + (VALUE(INDEX(SPLIT(P5,""/""),2))-VALUE(INDEX(SPLIT(P5,""/""),1))) "),0.0) -> 0 | U5: Domain: nan Ecosystem: Android, CouchDB, iOS/iPadOS Language: JavaScript Match: DOM: M (0/2)[] S (0/1)[] C (0/1)[] ECO: M (0/1)[] S (0/1)[] C (0/1)[] LING: M (0/1)[] S (1/2)[javascript] C (0/1)[] Collaboration:: 33-93: UNCOMMON 33-270: UNCOMMON 33-303: UNCOMMON | V5: Domain: Desktop Ecosystem: .NET Language: C# Match: DOM: M (1/2)[desktop] S (0/1)[] C (0/1)[] ECO: M (1/1)[.net] S (0/1)[] C (0/1)[] LING: M (1/1)[c#] S (0/2)[] C (0/1)[] Collaboration:: 303-33: UNCOMMON 303-93: UNCOMMON 303-270: UNCOMMON | W5: Domain: Web Ecosystem: Angular Language: TypeScript Match: DOM: M (1/2)[web] S (0/1)[] C (0/1)[] ECO: M (0/1)[] S (0/1)[] C (0/1)[] LING: M (0/1)[] S (1/2)[typescript] C (0/1)[] Collaboration:: 270-33: UNCOMMON 270-93: P82(,osf=0.567,slf=0.737) | 270-411: P82(,osf=0.567,slf=0.737) | 270-438: P82(,osf=0.567,slf=0.737) 270-303: UNCOMMON | X5: Domain: Desktop Ecosystem: .NET Language: C# Match: DOM: M (1/2)[desktop] S (0/1)[] C (0/1)[] ECO: M (1/1)[.net] S (0/1)[] C (0/1)[] LING: M (1/1)[c#] S (0/2)[] C (0/1)[] Collaboration:: 93-33: UNCOMMON 93-270: P82(,osf=0.567,slf=0.737) | 93-292: P82(,osf=0.567,slf=0.737) | 93-437: P158(,osf=0.670,slf=0.322); P82(,osf=0.567,slf=0.737); P85(,osf=0.784,slf=0.538) 93-303: UNCOMMON
C6: P1-TEAM5 | D6: Dev316 | E6: Dev389 | F6: Dev526 | G6: Dev308 | H6: 2 | I6: DOM M(1/2)[web] S(0/1)[] C(1/1)[mobile] | ECO M(0/1)[] S(1/1)[react] C(0/1)[] | LING M(0/1)[] S(1/2)[javascript] C(0/1)[] | J6: =IFERROR(__xludf.DUMMYFUNCTION("IFERROR(REGEXEXTRACT($I6,""DOM\s*M\((\d+/\d+)\)""),"""") "),"1/2") -> 1/2 | K6: =IFERROR(__xludf.DUMMYFUNCTION("IFERROR(REGEXEXTRACT($I6,""DOM.*?S\((\d+/\d+)\)""),"""") "),"0/1") -> 0/1 | L6: =IFERROR(__xludf.DUMMYFUNCTION("IFERROR(REGEXEXTRACT($I6,""DOM.*?C\((\d+/\d+)\)""),"""") "),"1/1") -> 1/1 | M6: =IFERROR(__xludf.DUMMYFUNCTION("IFERROR(REGEXEXTRACT($I6,""ECO\s*M\((\d+/\d+)\)""),"""") "),"0/1") -> 0/1 | N6: =IFERROR(__xludf.DUMMYFUNCTION("IFERROR(REGEXEXTRACT($I6,""ECO.*?S\((\d+/\d+)\)""),"""") "),"1/1") -> 1/1 | O6: =IFERROR(__xludf.DUMMYFUNCTION("IFERROR(REGEXEXTRACT($I6,""ECO.*?C\((\d+/\d+)\)""),"""") "),"0/1") -> 0/1 | P6: =IFERROR(__xludf.DUMMYFUNCTION("IFERROR(REGEXEXTRACT($I6,""LING\s*M\((\d+/\d+)\)""),"""") "),"0/1") -> 0/1 | Q6: =IFERROR(__xludf.DUMMYFUNCTION("IFERROR(REGEXEXTRACT($I6,""LING.*?S\((\d+/\d+)\)""),"""") "),"1/2") -> 1/2 | R6: =IFERROR(__xludf.DUMMYFUNCTION("IFERROR(REGEXEXTRACT($I6,""LING[^|]*C\(([0-9]+/[0-9]+)\)""),"""") "),"0/1") -> 0/1 | S6: =IFERROR(__xludf.DUMMYFUNCTION("AND( VALUE(INDEX(SPLIT(J6,""/""),1))=VALUE(INDEX(SPLIT(J6,""/""),2)), VALUE(INDEX(SPLIT(M6,""/""),1))=VALUE(INDEX(SPLIT(M6,""/""),2)), VALUE(INDEX(SPLIT(P6,""/""),1))=VALUE(INDEX(SPLIT(P6,""/""),2)) ) "),FALSE) -> FALSE | T6: =IFERROR(__xludf.DUMMYFUNCTION(" (VALUE(INDEX(SPLIT(J6,""/""),2))-VALUE(INDEX(SPLIT(J6,""/""),1))) + (VALUE(INDEX(SPLIT(M6,""/""),2))-VALUE(INDEX(SPLIT(M6,""/""),1))) + (VALUE(INDEX(SPLIT(P6,""/""),2))-VALUE(INDEX(SPLIT(P6,""/""),1))) "),3.0) -> 3 | U6: Domain: Web Ecosystem: Node.js Language: JavaScript Match: DOM: M (1/2)[web] S (0/1)[] C (0/1)[] ECO: M (0/1)[] S (0/1)[] C (0/1)[] LING: M (0/1)[] S (1/2)[javascript] C (0/1)[] Collaboration:: 316-308: UNCOMMON 316-389: UNCOMMON 316-526: UNCOMMON | V6: Domain: Mobile Ecosystem: Android Language: Kotlin Match: DOM: M (0/2)[] S (0/1)[] C (1/1)[mobile] ECO: M (0/1)[] S (0/1)[] C (0/1)[] LING: M (0/1)[] S (0/2)[] C (0/1)[] Collaboration:: 389-308: UNCOMMON 389-316: UNCOMMON 389-526: UNCOMMON | W6: Domain: Web Ecosystem: React Language: JavaScript Match: DOM: M (1/2)[web] S (0/1)[] C (0/1)[] ECO: M (0/1)[] S (1/1)[react] C (0/1)[] LING: M (0/1)[] S (1/2)[javascript] C (0/1)[] Collaboration:: 526-308: UNCOMMON 526-316: UNCOMMON 526-389: UNCOMMON | X6: Domain: Web Ecosystem: React Language: JavaScript Match: DOM: M (1/2)[web] S (0/1)[] C (0/1)[] ECO: M (0/1)[] S (1/1)[react] C (0/1)[] LING: M (0/1)[] S (1/2)[javascript] C (0/1)[] Collaboration:: 308-316: UNCOMMON 308-389: UNCOMMON 308-526: UNCOMMON
J7: =IFERROR(__xludf.DUMMYFUNCTION("IFERROR(REGEXEXTRACT($I7,""DOM\s*M\((\d+/\d+)\)""),"""") "),"") | K7: =IFERROR(__xludf.DUMMYFUNCTION("IFERROR(REGEXEXTRACT($I7,""DOM.*?S\((\d+/\d+)\)""),"""") "),"") | L7: =IFERROR(__xludf.DUMMYFUNCTION("IFERROR(REGEXEXTRACT($I7,""DOM.*?C\((\d+/\d+)\)""),"""") "),"") | M7: =IFERROR(__xludf.DUMMYFUNCTION("IFERROR(REGEXEXTRACT($I7,""ECO\s*M\((\d+/\d+)\)""),"""") "),"") | N7: =IFERROR(__xludf.DUMMYFUNCTION("IFERROR(REGEXEXTRACT($I7,""ECO.*?S\((\d+/\d+)\)""),"""") "),"") | O7: =IFERROR(__xludf.DUMMYFUNCTION("IFERROR(REGEXEXTRACT($I7,""ECO.*?C\((\d+/\d+)\)""),"""") "),"") | P7: =IFERROR(__xludf.DUMMYFUNCTION("IFERROR(REGEXEXTRACT($I7,""LING\s*M\((\d+/\d+)\)""),"""") "),"") | Q7: =IFERROR(__xludf.DUMMYFUNCTION("IFERROR(REGEXEXTRACT($I7,""LING.*?S\((\d+/\d+)\)""),"""") "),"") | R7: =IFERROR(__xludf.DUMMYFUNCTION("IFERROR(REGEXEXTRACT($I7,""LING[^|]*C\(([0-9]+/[0-9]+)\)""),"""") "),"")
A8: P2 | B8: =IFERROR(VLOOKUP(A8,Projects!$A$2:$C$7,2,FALSE),"") -> Hybrid Mobile App with Web Panel | C8: P2-TEAM1 | D8: Dev466 | E8: Dev93 | F8: Dev437 | G8: Dev292 | H8: 1 | I8: DOM M(1/1)[mobile] S(1/1)[web] C(0/1)[] | ECO M(1/2)[ios/ipados] S(0/1)[] C(1/1)[.net] | LING M(1/2)[swift] S(1/2)[javascript] C(1/2)[c#] | J8: =IFERROR(__xludf.DUMMYFUNCTION("IFERROR(REGEXEXTRACT($I8,""DOM\s*M\((\d+/\d+)\)""),"""") "),"1/1") -> 1/1 | K8: =IFERROR(__xludf.DUMMYFUNCTION("IFERROR(REGEXEXTRACT($I8,""DOM.*?S\((\d+/\d+)\)""),"""") "),"1/1") -> 1/1 | L8: =IFERROR(__xludf.DUMMYFUNCTION("IFERROR(REGEXEXTRACT($I8,""DOM.*?C\((\d+/\d+)\)""),"""") "),"0/1") -> 0/1 | M8: =IFERROR(__xludf.DUMMYFUNCTION("IFERROR(REGEXEXTRACT($I8,""ECO\s*M\((\d+/\d+)\)""),"""") "),"1/2") -> 1/2 | N8: =IFERROR(__xludf.DUMMYFUNCTION("IFERROR(REGEXEXTRACT($I8,""ECO.*?S\((\d+/\d+)\)""),"""") "),"0/1") -> 0/1 | O8: =IFERROR(__xludf.DUMMYFUNCTION("IFERROR(REGEXEXTRACT($I8,""ECO.*?C\((\d+/\d+)\)""),"""") "),"1/1") -> 1/1 | P8: =IFERROR(__xludf.DUMMYFUNCTION("IFERROR(REGEXEXTRACT($I8,""LING\s*M\((\d+/\d+)\)""),"""") "),"1/2") -> 1/2 | Q8: =IFERROR(__xludf.DUMMYFUNCTION("IFERROR(REGEXEXTRACT($I8,""LING.*?S\((\d+/\d+)\)""),"""") "),"1/2") -> 1/2 | R8: =IFERROR(__xludf.DUMMYFUNCTION("IFERROR(REGEXEXTRACT($I8,""LING[^|]*C\(([0-9]+/[0-9]+)\)""),"""") "),"1/2") -> 1/2 | S8: =IFERROR(__xludf.DUMMYFUNCTION("AND( VALUE(INDEX(SPLIT(J8,""/""),1))=VALUE(INDEX(SPLIT(J8,""/""),2)), VALUE(INDEX(SPLIT(M8,""/""),1))=VALUE(INDEX(SPLIT(M8,""/""),2)), VALUE(INDEX(SPLIT(P8,""/""),1))=VALUE(INDEX(SPLIT(P8,""/""),2)) ) "),FALSE) -> FALSE | T8: =IFERROR(__xludf.DUMMYFUNCTION(" (VALUE(INDEX(SPLIT(J8,""/""),2))-VALUE(INDEX(SPLIT(J8,""/""),1))) + (VALUE(INDEX(SPLIT(M8,""/""),2))-VALUE(INDEX(SPLIT(M8,""/""),1))) + (VALUE(INDEX(SPLIT(P8,""/""),2))-VALUE(INDEX(SPLIT(P8,""/""),1))) "),2.0) -> 2 | U8: Domain: Desktop Ecosystem: .NET Language: C# Match: DOM: M (0/1)[] S (0/1)[] C (0/1)[] ECO: M (0/2)[] S (0/1)[] C (1/1)[.net] LING: M (0/2)[] S (0/2)[] C (1/2)[c#] Collaboration:: 466-93: UNCOMMON 466-292: UNCOMMON 466-437: UNCOMMON | V8: Domain: Desktop Ecosystem: .NET Language: C# Match: DOM: M (0/1)[] S (0/1)[] C (0/1)[] ECO: M (0/2)[] S (0/1)[] C (1/1)[.net] LING: M (0/2)[] S (0/2)[] C (1/2)[c#] Collaboration:: 93-292: UNCOMMON 93-437: UNCOMMON 93-466: UNCOMMON | W8: Domain: Mobile Ecosystem: iOS/iPadOS Language: Swift Match: DOM: M (1/1)[mobile] S (0/1)[] C (0/1)[] ECO: M (1/2)[ios/ipados] S (0/1)[] C (0/1)[] LING: M (1/2)[swift] S (0/2)[] C (0/2)[] Collaboration:: 437-93: P158(,osf=0.670,slf=0.322); P82(,osf=0.567,slf=0.737); P85(,osf=0.784,slf=0.538) | 437-292: P82(,osf=0.567,slf=0.737) 437-292: UNCOMMON 437-466: UNCOMMON | X8: Domain: Web Ecosystem: Node.js Language: JavaScript Match: DOM: M (0/1)[] S (1/1)[web] C (0/1)[] ECO: M (0/2)[] S (0/1)[] C (0/1)[] LING: M (0/2)[] S (1/2)[javascript] C (0/2)[] Collaboration:: 292-93: P82(,osf=0.567,slf=0.737) | 292-437: P82(,osf=0.567,slf=0.737) 292-437: UNCOMMON 292-466: UNCOMMON
B9: =IFERROR( "DOM M["&VLOOKUP($A8,Projects!$A:$L,4,FALSE)&"] S["&VLOOKUP($A8,Projects!$A:$L,5,FALSE)&"] C["&VLOOKUP($A8,Projects!$A:$L,6,FALSE)&"]"&CHAR(10)& "ECO M["&VLOOKUP($A8,Projects!$A:$L,7,FALSE)&"] S["&VLOOKUP($A8,Projects!$A:$L,8,FALSE)&"] C["&VLOOKUP($A8,Projects!$A:$L,9,FALSE)&"]"&CHAR(10)& "LING M["&VLOOKUP($A8,Projects!$A:$L,10,FALSE)&"] S["&VLOOKUP($A8,Projects!$A:$L,11,FALSE)&"] C["&VLOOKUP($A8,Projects!$A:$L,12,FALSE)&"]" ,"") -> DOM M[Mobile] S[Web] C[Cloud] ECO M[Android, iOS/iPadOS] S[React] C[.NET] LING M[Kotlin, Swift] S[JavaScript, TypeScript] C[Java, C#] | C9: P2-TEAM2 | D9: Dev270 | E9: Dev411 | F9: Dev479 | G9: Dev503 | H9: 2 | I9: DOM M(0/1)[] S(1/1)[web] C(0/1)[] | ECO M(0/2)[] S(1/1)[react] C(0/1)[] | LING M(0/2)[] S(2/2)[javascript, typescript] C(1/2)[java] | J9: =IFERROR(__xludf.DUMMYFUNCTION("IFERROR(REGEXEXTRACT($I9,""DOM\s*M\((\d+/\d+)\)""),"""") "),"0/1") -> 0/1 | K9: =IFERROR(__xludf.DUMMYFUNCTION("IFERROR(REGEXEXTRACT($I9,""DOM.*?S\((\d+/\d+)\)""),"""") "),"1/1") -> 1/1 | L9: =IFERROR(__xludf.DUMMYFUNCTION("IFERROR(REGEXEXTRACT($I9,""DOM.*?C\((\d+/\d+)\)""),"""") "),"0/1") -> 0/1 | M9: =IFERROR(__xludf.DUMMYFUNCTION("IFERROR(REGEXEXTRACT($I9,""ECO\s*M\((\d+/\d+)\)""),"""") "),"0/2") -> 0/2 | N9: =IFERROR(__xludf.DUMMYFUNCTION("IFERROR(REGEXEXTRACT($I9,""ECO.*?S\((\d+/\d+)\)""),"""") "),"1/1") -> 1/1 | O9: =IFERROR(__xludf.DUMMYFUNCTION("IFERROR(REGEXEXTRACT($I9,""ECO.*?C\((\d+/\d+)\)""),"""") "),"0/1") -> 0/1 | P9: =IFERROR(__xludf.DUMMYFUNCTION("IFERROR(REGEXEXTRACT($I9,""LING\s*M\((\d+/\d+)\)""),"""") "),"0/2") -> 0/2 | Q9: =IFERROR(__xludf.DUMMYFUNCTION("IFERROR(REGEXEXTRACT($I9,""LING.*?S\((\d+/\d+)\)""),"""") "),"2/2") -> 2/2 | R9: =IFERROR(__xludf.DUMMYFUNCTION("IFERROR(REGEXEXTRACT($I9,""LING[^|]*C\(([0-9]+/[0-9]+)\)""),"""") "),"1/2") -> 1/2 | S9: =IFERROR(__xludf.DUMMYFUNCTION("AND( VALUE(INDEX(SPLIT(J9,""/""),1))=VALUE(INDEX(SPLIT(J9,""/""),2)), VALUE(INDEX(SPLIT(M9,""/""),1))=VALUE(INDEX(SPLIT(M9,""/""),2)), VALUE(INDEX(SPLIT(P9,""/""),1))=VALUE(INDEX(SPLIT(P9,""/""),2)) ) "),FALSE) -> FALSE | T9: =IFERROR(__xludf.DUMMYFUNCTION(" (VALUE(INDEX(SPLIT(J9,""/""),2))-VALUE(INDEX(SPLIT(J9,""/""),1))) + (VALUE(INDEX(SPLIT(M9,""/""),2))-VALUE(INDEX(SPLIT(M9,""/""),1))) + (VALUE(INDEX(SPLIT(P9,""/""),2))-VALUE(INDEX(SPLIT(P9,""/""),1))) "),5.0) -> 5 | U9: Domain: Web Ecosystem: Angular Language: TypeScript Match: DOM: M (0/1)[] S (1/1)[web] C (0/1)[] ECO: M (0/2)[] S (0/1)[] C (0/1)[] LING: M (0/2)[] S (1/2)[typescript] C (0/2)[] Collaboration:: 270-411: UNCOMMON 270-479: UNCOMMON 270-503: UNCOMMON | V9: Domain: Web Ecosystem: Spring Boot Language: Java Match: DOM: M (0/1)[] S (1/1)[web] C (0/1)[] ECO: M (0/2)[] S (0/1)[] C (0/1)[] LING: M (0/2)[] S (0/2)[] C (1/2)[java] Collaboration:: 411-270: P82(,osf=0.567,slf=0.737) | 411-479: P179(,osf=0.489,slf=0.711) | 411-503: P145(,osf=0.612,slf=0.871); P177(,osf=0.340,slf=0.621); P284(,osf=0.383,slf=0.553) 411-479: UNCOMMON 411-503: UNCOMMON | W9: Domain: Web Ecosystem: Angular Language: TypeScript Match: DOM: M (0/1)[] S (1/1)[web] C (0/1)[] ECO: M (0/2)[] S (0/1)[] C (0/1)[] LING: M (0/2)[] S (1/2)[typescript] C (0/2)[] Collaboration:: 479-270: UNCOMMON 479-411: P179(,osf=0.489,slf=0.711) 479-503: UNCOMMON | X9: Domain: Web Ecosystem: React Language: JavaScript Match: DOM: M (0/1)[] S (1/1)[web] C (0/1)[] ECO: M (0/2)[] S (1/1)[react] C (0/1)[] LING: M (0/2)[] S (1/2)[javascript] C (0/2)[] Collaboration:: 503-270: UNCOMMON 503-411: UNCOMMON 503-479: UNCOMMON
C10: P2-TEAM3 | D10: Dev115 | E10: Dev119 | F10: Dev399 | G10: Dev193 | H10: 3 | I10: DOM M(1/1)[mobile] S(1/1)[web] C(0/1)[] | ECO M(1/2)[ios/ipados] S(0/1)[] C(1/1)[.net] | LING M(1/2)[swift] S(1/2)[javascript] C(2/2)[java, c#] | J10: =IFERROR(__xludf.DUMMYFUNCTION("IFERROR(REGEXEXTRACT($I10,""DOM\s*M\((\d+/\d+)\)""),"""") "),"1/1") -> 1/1 | K10: =IFERROR(__xludf.DUMMYFUNCTION("IFERROR(REGEXEXTRACT($I10,""DOM.*?S\((\d+/\d+)\)""),"""") "),"1/1") -> 1/1 | L10: =IFERROR(__xludf.DUMMYFUNCTION("IFERROR(REGEXEXTRACT($I10,""DOM.*?C\((\d+/\d+)\)""),"""") "),"0/1") -> 0/1 | M10: =IFERROR(__xludf.DUMMYFUNCTION("IFERROR(REGEXEXTRACT($I10,""ECO\s*M\((\d+/\d+)\)""),"""") "),"1/2") -> 1/2 | N10: =IFERROR(__xludf.DUMMYFUNCTION("IFERROR(REGEXEXTRACT($I10,""ECO.*?S\((\d+/\d+)\)""),"""") "),"0/1") -> 0/1 | O10: =IFERROR(__xludf.DUMMYFUNCTION("IFERROR(REGEXEXTRACT($I10,""ECO.*?C\((\d+/\d+)\)""),"""") "),"1/1") -> 1/1 | P10: =IFERROR(__xludf.DUMMYFUNCTION("IFERROR(REGEXEXTRACT($I10,""LING\s*M\((\d+/\d+)\)""),"""") "),"1/2") -> 1/2 | Q10: =IFERROR(__xludf.DUMMYFUNCTION("IFERROR(REGEXEXTRACT($I10,""LING.*?S\((\d+/\d+)\)""),"""") "),"1/2") -> 1/2 | R10: =IFERROR(__xludf.DUMMYFUNCTION("IFERROR(REGEXEXTRACT($I10,""LING[^|]*C\(([0-9]+/[0-9]+)\)""),"""") "),"2/2") -> 2/2 | S10: =IFERROR(__xludf.DUMMYFUNCTION("AND( VALUE(INDEX(SPLIT(J10,""/""),1))=VALUE(INDEX(SPLIT(J10,""/""),2)), VALUE(INDEX(SPLIT(M10,""/""),1))=VALUE(INDEX(SPLIT(M10,""/""),2)), VALUE(INDEX(SPLIT(P10,""/""),1))=VALUE(INDEX(SPLIT(P10,""/""),2)) ) "),FALSE) -> FALSE | T10: =IFERROR(__xludf.DUMMYFUNCTION(" (VALUE(INDEX(SPLIT(J10,""/""),2))-VALUE(INDEX(SPLIT(J10,""/""),1))) + (VALUE(INDEX(SPLIT(M10,""/""),2))-VALUE(INDEX(SPLIT(M10,""/""),1))) + (VALUE(INDEX(SPLIT(P10,""/""),2))-VALUE(INDEX(SPLIT(P10,""/""),1))) "),2.0) -> 2 | U10: Domain: Web Ecosystem: Node.js Language: JavaScript Match: DOM: M (0/1)[] S (1/1)[web] C (0/1)[] ECO: M (0/2)[] S (0/1)[] C (0/1)[] LING: M (0/2)[] S (1/2)[javascript] C (0/2)[] Collaboration:: 115-119: UNCOMMON 115-193: UNCOMMON 115-399: UNCOMMON | V10: Domain: Mobile Ecosystem: iOS/iPadOS Language: Swift Match: DOM: M (1/1)[mobile] S (0/1)[] C (0/1)[] ECO: M (1/2)[ios/ipados] S (0/1)[] C (0/1)[] LING: M (1/2)[swift] S (0/2)[] C (0/2)[] Collaboration:: 119-115: UNCOMMON 119-193: P82(,osf=0.567,slf=0.737) | 119-399: P82(,osf=0.567,slf=0.737) 119-399: UNCOMMON | W10: Domain: Desktop Ecosystem: .NET Language: C# Match: DOM: M (0/1)[] S (0/1)[] C (0/1)[] ECO: M (0/2)[] S (0/1)[] C (1/1)[.net] LING: M (0/2)[] S (0/2)[] C (1/2)[c#] Collaboration:: 399-115: UNCOMMON 399-119: P82(,osf=0.567,slf=0.737) | 399-193: P82(,osf=0.567,slf=0.737); P85(,osf=0.784,slf=0.538) 399-193: UNCOMMON | X10: Domain: Web Ecosystem: Spring Boot Language: Java Match: DOM: M (0/1)[] S (1/1)[web] C (0/1)[] ECO: M (0/2)[] S (0/1)[] C (0/1)[] LING: M (0/2)[] S (0/2)[] C (1/2)[java] Collaboration:: 193-115: UNCOMMON 193-119: UNCOMMON 193-399: UNCOMMON
C11: P2-TEAM4 | D11: Dev468 | E11: Dev263 | F11: Dev503 | G11: Dev5 | H11: 4 | I11: DOM M(1/1)[mobile] S(1/1)[web] C(1/1)[cloud] | ECO M(1/2)[android] S(1/1)[react] C(0/1)[] | LING M(1/2)[kotlin] S(1/2)[javascript] C(0/2)[] | J11: =IFERROR(__xludf.DUMMYFUNCTION("IFERROR(REGEXEXTRACT($I11,""DOM\s*M\((\d+/\d+)\)""),"""") "),"1/1") -> 1/1 | K11: =IFERROR(__xludf.DUMMYFUNCTION("IFERROR(REGEXEXTRACT($I11,""DOM.*?S\((\d+/\d+)\)""),"""") "),"1/1") -> 1/1 | L11: =IFERROR(__xludf.DUMMYFUNCTION("IFERROR(REGEXEXTRACT($I11,""DOM.*?C\((\d+/\d+)\)""),"""") "),"1/1") -> 1/1 | M11: =IFERROR(__xludf.DUMMYFUNCTION("IFERROR(REGEXEXTRACT($I11,""ECO\s*M\((\d+/\d+)\)""),"""") "),"1/2") -> 1/2 | N11: =IFERROR(__xludf.DUMMYFUNCTION("IFERROR(REGEXEXTRACT($I11,""ECO.*?S\((\d+/\d+)\)""),"""") "),"1/1") -> 1/1 | O11: =IFERROR(__xludf.DUMMYFUNCTION("IFERROR(REGEXEXTRACT($I11,""ECO.*?C\((\d+/\d+)\)""),"""") "),"0/1") -> 0/1 | P11: =IFERROR(__xludf.DUMMYFUNCTION("IFERROR(REGEXEXTRACT($I11,""LING\s*M\((\d+/\d+)\)""),"""") "),"1/2") -> 1/2 | Q11: =IFERROR(__xludf.DUMMYFUNCTION("IFERROR(REGEXEXTRACT($I11,""LING.*?S\((\d+/\d+)\)""),"""") "),"1/2") -> 1/2 | R11: =IFERROR(__xludf.DUMMYFUNCTION("IFERROR(REGEXEXTRACT($I11,""LING[^|]*C\(([0-9]+/[0-9]+)\)""),"""") "),"0/2") -> 0/2 | S11: =IFERROR(__xludf.DUMMYFUNCTION("AND( VALUE(INDEX(SPLIT(J11,""/""),1))=VALUE(INDEX(SPLIT(J11,""/""),2)), VALUE(INDEX(SPLIT(M11,""/""),1))=VALUE(INDEX(SPLIT(M11,""/""),2)), VALUE(INDEX(SPLIT(P11,""/""),1))=VALUE(INDEX(SPLIT(P11,""/""),2)) ) "),FALSE) -> FALSE | T11: =IFERROR(__xludf.DUMMYFUNCTION(" (VALUE(INDEX(SPLIT(J11,""/""),2))-VALUE(INDEX(SPLIT(J11,""/""),1))) + (VALUE(INDEX(SPLIT(M11,""/""),2))-VALUE(INDEX(SPLIT(M11,""/""),1))) + (VALUE(INDEX(SPLIT(P11,""/""),2))-VALUE(INDEX(SPLIT(P11,""/""),1))) "),2.0) -> 2 | U11: Domain: Cloud Ecosystem: AWS Lambda Language: Python Match: DOM: M (0/1)[] S (0/1)[] C (1/1)[cloud] ECO: M (0/2)[] S (0/1)[] C (0/1)[] LING: M (0/2)[] S (0/2)[] C (0/2)[] Collaboration:: 468-5: P82(,osf=0.567,slf=0.737) | 468-508: P196(,osf=0.888,slf=0.339) | 468-516: P82(,osf=0.567,slf=0.737); P85(,osf=0.784,slf=0.538) 468-263: UNCOMMON 468-503: UNCOMMON | V11: Domain: Web Ecosystem: Vue Language: JavaScript Match: DOM: M (0/1)[] S (1/1)[web] C (0/1)[] ECO: M (0/2)[] S (0/1)[] C (0/1)[] LING: M (0/2)[] S (1/2)[javascript] C (0/2)[] Collaboration:: 263-5: P179(,osf=0.489,slf=0.711) | 263-145: P179(,osf=0.489,slf=0.711); P201(,osf=0.535,slf=0.596) 263-468: UNCOMMON 263-503: UNCOMMON | W11: Domain: Web Ecosystem: React Language: JavaScript Match: DOM: M (0/1)[] S (1/1)[web] C (0/1)[] ECO: M (0/2)[] S (1/1)[react] C (0/1)[] LING: M (0/2)[] S (1/2)[javascript] C (0/2)[] Collaboration:: 503-5: P145(,osf=0.612,slf=0.871); P177(,osf=0.340,slf=0.621); P213(,osf=0.312,slf=0.608); P216(,osf=0.401,slf=0.341); P279(,osf=0.594,slf=0.422) | 503-411: P145(,osf=0.612,slf=0.871); P177(,osf=0.340,slf=0.621); P284(,osf=0.383,slf=0.553) 503-263: UNCOMMON 503-468: UNCOMMON | X11: Domain: Mobile Ecosystem: Android Language: Kotlin Match: DOM: M (1/1)[mobile] S (0/1)[] C (0/1)[] ECO: M (1/2)[android] S (0/1)[] C (0/1)[] LING: M (1/2)[kotlin] S (0/2)[] C (0/2)[] Collaboration:: 5-263: P179(,osf=0.489,slf=0.711) | 5-468: P82(,osf=0.567,slf=0.737) | 5-503: P145(,osf=0.612,slf=0.871); P177(,osf=0.340,slf=0.621); P213(,osf=0.312,slf=0.608); P216(,osf=0.401,slf=0.341); P279(,osf=0.594,slf=0.422) 5-468: UNCOMMON 5-503: UNCOMMON
C12: P2-TEAM5 | D12: Dev104 | E12: Dev363 | F12: Dev544 | G12: Dev81 | H12: 3 | I12: DOM M(1/1)[mobile] S(0/1)[] C(0/1)[] | ECO M(2/2)[android, ios/ipados] S(0/1)[] C(0/1)[] | LING M(2/2)[kotlin, swift] S(1/2)[javascript] C(0/2)[] | J12: =IFERROR(__xludf.DUMMYFUNCTION("IFERROR(REGEXEXTRACT($I12,""DOM\s*M\((\d+/\d+)\)""),"""") "),"1/1") -> 1/1 | K12: =IFERROR(__xludf.DUMMYFUNCTION("IFERROR(REGEXEXTRACT($I12,""DOM.*?S\((\d+/\d+)\)""),"""") "),"0/1") -> 0/1 | L12: =IFERROR(__xludf.DUMMYFUNCTION("IFERROR(REGEXEXTRACT($I12,""DOM.*?C\((\d+/\d+)\)""),"""") "),"0/1") -> 0/1 | M12: =IFERROR(__xludf.DUMMYFUNCTION("IFERROR(REGEXEXTRACT($I12,""ECO\s*M\((\d+/\d+)\)""),"""") "),"2/2") -> 2/2 | N12: =IFERROR(__xludf.DUMMYFUNCTION("IFERROR(REGEXEXTRACT($I12,""ECO.*?S\((\d+/\d+)\)""),"""") "),"0/1") -> 0/1 | O12: =IFERROR(__xludf.DUMMYFUNCTION("IFERROR(REGEXEXTRACT($I12,""ECO.*?C\((\d+/\d+)\)""),"""") "),"0/1") -> 0/1 | P12: =IFERROR(__xludf.DUMMYFUNCTION("IFERROR(REGEXEXTRACT($I12,""LING\s*M\((\d+/\d+)\)""),"""") "),"2/2") -> 2/2 | Q12: =IFERROR(__xludf.DUMMYFUNCTION("IFERROR(REGEXEXTRACT($I12,""LING.*?S\((\d+/\d+)\)""),"""") "),"1/2") -> 1/2 | R12: =IFERROR(__xludf.DUMMYFUNCTION("IFERROR(REGEXEXTRACT($I12,""LING[^|]*C\(([0-9]+/[0-9]+)\)""),"""") "),"0/2") -> 0/2 | S12: =IFERROR(__xludf.DUMMYFUNCTION("AND( VALUE(INDEX(SPLIT(J12,""/""),1))=VALUE(INDEX(SPLIT(J12,""/""),2)), VALUE(INDEX(SPLIT(M12,""/""),1))=VALUE(INDEX(SPLIT(M12,""/""),2)), VALUE(INDEX(SPLIT(P12,""/""),1))=VALUE(INDEX(SPLIT(P12,""/""),2)) ) "),TRUE) -> TRUE | T12: =IFERROR(__xludf.DUMMYFUNCTION(" (VALUE(INDEX(SPLIT(J12,""/""),2))-VALUE(INDEX(SPLIT(J12,""/""),1))) + (VALUE(INDEX(SPLIT(M12,""/""),2))-VALUE(INDEX(SPLIT(M12,""/""),1))) + (VALUE(INDEX(SPLIT(P12,""/""),2))-VALUE(INDEX(SPLIT(P12,""/""),1))) "),0.0) -> 0 | U12: Domain: Mobile Ecosystem: Android Language: Kotlin Match: DOM: M (1/1)[mobile] S (0/1)[] C (0/1)[] ECO: M (1/2)[android] S (0/1)[] C (0/1)[] LING: M (1/2)[kotlin] S (0/2)[] C (0/2)[] Collaboration:: 104-81: P69(,osf=0.478,slf=0.301) 104-363: UNCOMMON 104-544: UNCOMMON | V12: Domain: Mobile Ecosystem: iOS/iPadOS Language: Swift Match: DOM: M (1/1)[mobile] S (0/1)[] C (0/1)[] ECO: M (1/2)[ios/ipados] S (0/1)[] C (0/1)[] LING: M (1/2)[swift] S (0/2)[] C (0/2)[] Collaboration:: 363-81: UNCOMMON 363-104: UNCOMMON 363-544: UNCOMMON | W12: Domain: Mobile Ecosystem: iOS/iPadOS Language: Swift Match: DOM: M (1/1)[mobile] S (0/1)[] C (0/1)[] ECO: M (1/2)[ios/ipados] S (0/1)[] C (0/1)[] LING: M (1/2)[swift] S (0/2)[] C (0/2)[] Collaboration:: 544-81: UNCOMMON 544-104: UNCOMMON 544-363: UNCOMMON | X12: Domain: IoT Ecosystem: nan Language: JavaScript Match: DOM: M (0/1)[] S (0/1)[] C (0/1)[] ECO: M (0/2)[] S (0/1)[] C (0/1)[] LING: M (0/2)[] S (1/2)[javascript] C (0/2)[] Collaboration:: 81-104: P69(,osf=0.478,slf=0.301) 81-363: UNCOMMON 81-544: UNCOMMON
J13: =IFERROR(__xludf.DUMMYFUNCTION("IFERROR(REGEXEXTRACT($I13,""DOM\s*M\((\d+/\d+)\)""),"""") "),"") | K13: =IFERROR(__xludf.DUMMYFUNCTION("IFERROR(REGEXEXTRACT($I13,""DOM.*?S\((\d+/\d+)\)""),"""") "),"") | L13: =IFERROR(__xludf.DUMMYFUNCTION("IFERROR(REGEXEXTRACT($I13,""DOM.*?C\((\d+/\d+)\)""),"""") "),"") | M13: =IFERROR(__xludf.DUMMYFUNCTION("IFERROR(REGEXEXTRACT($I13,""ECO\s*M\((\d+/\d+)\)""),"""") "),"") | N13: =IFERROR(__xludf.DUMMYFUNCTION("IFERROR(REGEXEXTRACT($I13,""ECO.*?S\((\d+/\d+)\)""),"""") "),"") | O13: =IFERROR(__xludf.DUMMYFUNCTION("IFERROR(REGEXEXTRACT($I13,""ECO.*?C\((\d+/\d+)\)""),"""") "),"") | P13: =IFERROR(__xludf.DUMMYFUNCTION("IFERROR(REGEXEXTRACT($I13,""LING\s*M\((\d+/\d+)\)""),"""") "),"") | Q13: =IFERROR(__xludf.DUMMYFUNCTION("IFERROR(REGEXEXTRACT($I13,""LING.*?S\((\d+/\d+)\)""),"""") "),"") | R13: =IFERROR(__xludf.DUMMYFUNCTION("IFERROR(REGEXEXTRACT($I13,""LING[^|]*C\(([0-9]+/[0-9]+)\)""),"""") "),"")
A14: P3 | B14: =IFERROR(VLOOKUP(A14,Projects!$A$2:$C$7,2,FALSE),"") -> Cloud IoT Sensor Platform | C14: P3-TEAM1 | D14: Dev423 | E14: Dev558 | F14: Dev494 | G14: Dev391 | H14: 3 | I14: DOM M(1/2)[cloud] S(1/1)[web] C(0/1)[] | ECO M(1/1)[aws lambda] S(1/3)[react] C(1/1)[android] | LING M(1/2)[python] S(1/1)[javascript] C(0/2)[] | J14: =IFERROR(__xludf.DUMMYFUNCTION("IFERROR(REGEXEXTRACT($I14,""DOM\s*M\((\d+/\d+)\)""),"""") "),"1/2") -> 1/2 | K14: =IFERROR(__xludf.DUMMYFUNCTION("IFERROR(REGEXEXTRACT($I14,""DOM.*?S\((\d+/\d+)\)""),"""") "),"1/1") -> 1/1 | L14: =IFERROR(__xludf.DUMMYFUNCTION("IFERROR(REGEXEXTRACT($I14,""DOM.*?C\((\d+/\d+)\)""),"""") "),"0/1") -> 0/1 | M14: =IFERROR(__xludf.DUMMYFUNCTION("IFERROR(REGEXEXTRACT($I14,""ECO\s*M\((\d+/\d+)\)""),"""") "),"1/1") -> 1/1 | N14: =IFERROR(__xludf.DUMMYFUNCTION("IFERROR(REGEXEXTRACT($I14,""ECO.*?S\((\d+/\d+)\)""),"""") "),"1/3") -> 1/3 | O14: =IFERROR(__xludf.DUMMYFUNCTION("IFERROR(REGEXEXTRACT($I14,""ECO.*?C\((\d+/\d+)\)""),"""") "),"1/1") -> 1/1 | P14: =IFERROR(__xludf.DUMMYFUNCTION("IFERROR(REGEXEXTRACT($I14,""LING\s*M\((\d+/\d+)\)""),"""") "),"1/2") -> 1/2 | Q14: =IFERROR(__xludf.DUMMYFUNCTION("IFERROR(REGEXEXTRACT($I14,""LING.*?S\((\d+/\d+)\)""),"""") "),"1/1") -> 1/1 | R14: =IFERROR(__xludf.DUMMYFUNCTION("IFERROR(REGEXEXTRACT($I14,""LING[^|]*C\(([0-9]+/[0-9]+)\)""),"""") "),"0/2") -> 0/2 | S14: =IFERROR(__xludf.DUMMYFUNCTION("AND( VALUE(INDEX(SPLIT(J14,""/""),1))=VALUE(INDEX(SPLIT(J14,""/""),2)), VALUE(INDEX(SPLIT(M14,""/""),1))=VALUE(INDEX(SPLIT(M14,""/""),2)), VALUE(INDEX(SPLIT(P14,""/""),1))=VALUE(INDEX(SPLIT(P14,""/""),2)) ) "),FALSE) -> FALSE | T14: =IFERROR(__xludf.DUMMYFUNCTION(" (VALUE(INDEX(SPLIT(J14,""/""),2))-VALUE(INDEX(SPLIT(J14,""/""),1))) + (VALUE(INDEX(SPLIT(M14,""/""),2))-VALUE(INDEX(SPLIT(M14,""/""),1))) + (VALUE(INDEX(SPLIT(P14,""/""),2))-VALUE(INDEX(SPLIT(P14,""/""),1))) "),2.0) -> 2 | U14: Domain: Web Ecosystem: React Language: JavaScript Match: DOM: M (0/2)[] S (1/1)[web] C (0/1)[] ECO: M (0/1)[] S (1/3)[react] C (0/1)[] LING: M (0/2)[] S (1/1)[javascript] C (0/2)[] Collaboration:: 423-391: UNCOMMON 423-494: UNCOMMON 423-558: P85(,osf=0.784,slf=0.538) | V14: Domain: Mobile Ecosystem: Android Language: Kotlin Match: DOM: M (0/2)[] S (0/1)[] C (0/1)[] ECO: M (0/1)[] S (0/3)[] C (1/1)[android] LING: M (0/2)[] S (0/1)[] C (0/2)[] Collaboration:: 558-391: UNCOMMON 558-423: UNCOMMON 558-494: UNCOMMON | W14: Domain: Cloud Ecosystem: AWS Lambda Language: Python Match: DOM: M (1/2)[cloud] S (0/1)[] C (0/1)[] ECO: M (1/1)[aws lambda] S (0/3)[] C (0/1)[] LING: M (1/2)[python] S (0/1)[] C (0/2)[] Collaboration:: 494-391: UNCOMMON 494-423: UNCOMMON 494-558: UNCOMMON | X14: Domain: Cloud Ecosystem: AWS Lambda Language: Python Match: DOM: M (1/2)[cloud] S (0/1)[] C (0/1)[] ECO: M (1/1)[aws lambda] S (0/3)[] C (0/1)[] LING: M (1/2)[python] S (0/1)[] C (0/2)[] Collaboration:: 391-423: UNCOMMON 391-494: UNCOMMON 391-558: UNCOMMON
B15: =IFERROR( "DOM M["&VLOOKUP($A14,Projects!$A:$L,4,FALSE)&"] S["&VLOOKUP($A14,Projects!$A:$L,5,FALSE)&"] C["&VLOOKUP($A14,Projects!$A:$L,6,FALSE)&"]"&CHAR(10)& "ECO M["&VLOOKUP($A14,Projects!$A:$L,7,FALSE)&"] S["&VLOOKUP($A14,Projects!$A:$L,8,FALSE)&"] C["&VLOOKUP($A14,Projects!$A:$L,9,FALSE)&"]"&CHAR(10)& "LING M["&VLOOKUP($A14,Projects!$A:$L,10,FALSE)&"] S["&VLOOKUP($A14,Projects!$A:$L,11,FALSE)&"] C["&VLOOKUP($A14,Projects!$A:$L,12,FALSE)&"]" ,"") -> DOM M[IoT, Cloud] S[Web] C[Desktop] ECO M[AWS Lambda] S[React, Angular, MongoDB] C[Android] LING M[Python, C++] S[JavaScript] C[Java, TypeScript] | C15: P3-TEAM2 | D15: Dev104 | E15: Dev446 | F15: Dev152 | G15: Dev465 | H15: 5 | I15: DOM M(0/2)[] S(1/1)[web] C(0/1)[] | ECO M(0/1)[] S(1/3)[react] C(1/1)[android] | LING M(0/2)[] S(1/1)[javascript] C(1/2)[java] | J15: =IFERROR(__xludf.DUMMYFUNCTION("IFERROR(REGEXEXTRACT($I15,""DOM\s*M\((\d+/\d+)\)""),"""") "),"0/2") -> 0/2 | K15: =IFERROR(__xludf.DUMMYFUNCTION("IFERROR(REGEXEXTRACT($I15,""DOM.*?S\((\d+/\d+)\)""),"""") "),"1/1") -> 1/1 | L15: =IFERROR(__xludf.DUMMYFUNCTION("IFERROR(REGEXEXTRACT($I15,""DOM.*?C\((\d+/\d+)\)""),"""") "),"0/1") -> 0/1 | M15: =IFERROR(__xludf.DUMMYFUNCTION("IFERROR(REGEXEXTRACT($I15,""ECO\s*M\((\d+/\d+)\)""),"""") "),"0/1") -> 0/1 | N15: =IFERROR(__xludf.DUMMYFUNCTION("IFERROR(REGEXEXTRACT($I15,""ECO.*?S\((\d+/\d+)\)""),"""") "),"1/3") -> 1/3 | O15: =IFERROR(__xludf.DUMMYFUNCTION("IFERROR(REGEXEXTRACT($I15,""ECO.*?C\((\d+/\d+)\)""),"""") "),"1/1") -> 1/1 | P15: =IFERROR(__xludf.DUMMYFUNCTION("IFERROR(REGEXEXTRACT($I15,""LING\s*M\((\d+/\d+)\)""),"""") "),"0/2") -> 0/2 | Q15: =IFERROR(__xludf.DUMMYFUNCTION("IFERROR(REGEXEXTRACT($I15,""LING.*?S\((\d+/\d+)\)""),"""") "),"1/1") -> 1/1 | R15: =IFERROR(__xludf.DUMMYFUNCTION("IFERROR(REGEXEXTRACT($I15,""LING[^|]*C\(([0-9]+/[0-9]+)\)""),"""") "),"1/2") -> 1/2 | S15: =IFERROR(__xludf.DUMMYFUNCTION("AND( VALUE(INDEX(SPLIT(J15,""/""),1))=VALUE(INDEX(SPLIT(J15,""/""),2)), VALUE(INDEX(SPLIT(M15,""/""),1))=VALUE(INDEX(SPLIT(M15,""/""),2)), VALUE(INDEX(SPLIT(P15,""/""),1))=VALUE(INDEX(SPLIT(P15,""/""),2)) ) "),FALSE) -> FALSE | T15: =IFERROR(__xludf.DUMMYFUNCTION(" (VALUE(INDEX(SPLIT(J15,""/""),2))-VALUE(INDEX(SPLIT(J15,""/""),1))) + (VALUE(INDEX(SPLIT(M15,""/""),2))-VALUE(INDEX(SPLIT(M15,""/""),1))) + (VALUE(INDEX(SPLIT(P15,""/""),2))-VALUE(INDEX(SPLIT(P15,""/""),1))) "),5.0) -> 5 | U15: Domain: Mobile Ecosystem: Android Language: Kotlin Match: DOM: M (0/2)[] S (0/1)[] C (0/1)[] ECO: M (0/1)[] S (0/3)[] C (1/1)[android] LING: M (0/2)[] S (0/1)[] C (0/2)[] Collaboration:: 104-152: UNCOMMON 104-446: UNCOMMON 104-465: UNCOMMON | V15: Domain: Mobile Ecosystem: Android Language: Kotlin Match: DOM: M (0/2)[] S (0/1)[] C (0/1)[] ECO: M (0/1)[] S (0/3)[] C (1/1)[android] LING: M (0/2)[] S (0/1)[] C (0/2)[] Collaboration:: 446-104: UNCOMMON 446-152: UNCOMMON 446-465: UNCOMMON | W15: Domain: Web Ecosystem: React Language: JavaScript Match: DOM: M (0/2)[] S (1/1)[web] C (0/1)[] ECO: M (0/1)[] S (1/3)[react] C (0/1)[] LING: M (0/2)[] S (1/1)[javascript] C (0/2)[] Collaboration:: 152-104: UNCOMMON 152-446: UNCOMMON 152-465: UNCOMMON | X15: Domain: Web Ecosystem: Spring Boot Language: Java Match: DOM: M (0/2)[] S (1/1)[web] C (0/1)[] ECO: M (0/1)[] S (0/3)[] C (0/1)[] LING: M (0/2)[] S (0/1)[] C (1/2)[java] Collaboration:: 465-104: UNCOMMON 465-152: UNCOMMON 465-446: UNCOMMON
C16: P3-TEAM3 | D16: Dev362 | E16: Dev242 | F16: Dev450 | G16: Dev161 | H16: 4 | I16: DOM M(0/2)[] S(1/1)[web] C(1/1)[desktop] | ECO M(0/1)[] S(1/3)[react] C(0/1)[] | LING M(0/2)[] S(1/1)[javascript] C(0/2)[] | J16: =IFERROR(__xludf.DUMMYFUNCTION("IFERROR(REGEXEXTRACT($I16,""DOM\s*M\((\d+/\d+)\)""),"""") "),"0/2") -> 0/2 | K16: =IFERROR(__xludf.DUMMYFUNCTION("IFERROR(REGEXEXTRACT($I16,""DOM.*?S\((\d+/\d+)\)""),"""") "),"1/1") -> 1/1 | L16: =IFERROR(__xludf.DUMMYFUNCTION("IFERROR(REGEXEXTRACT($I16,""DOM.*?C\((\d+/\d+)\)""),"""") "),"1/1") -> 1/1 | M16: =IFERROR(__xludf.DUMMYFUNCTION("IFERROR(REGEXEXTRACT($I16,""ECO\s*M\((\d+/\d+)\)""),"""") "),"0/1") -> 0/1 | N16: =IFERROR(__xludf.DUMMYFUNCTION("IFERROR(REGEXEXTRACT($I16,""ECO.*?S\((\d+/\d+)\)""),"""") "),"1/3") -> 1/3 | O16: =IFERROR(__xludf.DUMMYFUNCTION("IFERROR(REGEXEXTRACT($I16,""ECO.*?C\((\d+/\d+)\)""),"""") "),"0/1") -> 0/1 | P16: =IFERROR(__xludf.DUMMYFUNCTION("IFERROR(REGEXEXTRACT($I16,""LING\s*M\((\d+/\d+)\)""),"""") "),"0/2") -> 0/2 | Q16: =IFERROR(__xludf.DUMMYFUNCTION("IFERROR(REGEXEXTRACT($I16,""LING.*?S\((\d+/\d+)\)""),"""") "),"1/1") -> 1/1 | R16: =IFERROR(__xludf.DUMMYFUNCTION("IFERROR(REGEXEXTRACT($I16,""LING[^|]*C\(([0-9]+/[0-9]+)\)""),"""") "),"0/2") -> 0/2 | S16: =IFERROR(__xludf.DUMMYFUNCTION("AND( VALUE(INDEX(SPLIT(J16,""/""),1))=VALUE(INDEX(SPLIT(J16,""/""),2)), VALUE(INDEX(SPLIT(M16,""/""),1))=VALUE(INDEX(SPLIT(M16,""/""),2)), VALUE(INDEX(SPLIT(P16,""/""),1))=VALUE(INDEX(SPLIT(P16,""/""),2)) ) "),FALSE) -> FALSE | T16: =IFERROR(__xludf.DUMMYFUNCTION(" (VALUE(INDEX(SPLIT(J16,""/""),2))-VALUE(INDEX(SPLIT(J16,""/""),1))) + (VALUE(INDEX(SPLIT(M16,""/""),2))-VALUE(INDEX(SPLIT(M16,""/""),1))) + (VALUE(INDEX(SPLIT(P16,""/""),2))-VALUE(INDEX(SPLIT(P16,""/""),1))) "),5.0) -> 5 | U16: Domain: Web Ecosystem: React Language: JavaScript Match: DOM: M (0/2)[] S (1/1)[web] C (0/1)[] ECO: M (0/1)[] S (1/3)[react] C (0/1)[] LING: M (0/2)[] S (1/1)[javascript] C (0/2)[] Collaboration:: 362-161: UNCOMMON 362-242: UNCOMMON 362-450: UNCOMMON | V16: Domain: Web Ecosystem: Node.js Language: JavaScript Match: DOM: M (0/2)[] S (1/1)[web] C (0/1)[] ECO: M (0/1)[] S (0/3)[] C (0/1)[] LING: M (0/2)[] S (1/1)[javascript] C (0/2)[] Collaboration:: 242-161: UNCOMMON 242-362: UNCOMMON 242-450: UNCOMMON | W16: Domain: Desktop Ecosystem: .NET Language: C# Match: DOM: M (0/2)[] S (0/1)[] C (1/1)[desktop] ECO: M (0/1)[] S (0/3)[] C (0/1)[] LING: M (0/2)[] S (0/1)[] C (0/2)[] Collaboration:: 450-161: UNCOMMON 450-242: UNCOMMON 450-362: UNCOMMON | X16: Domain: nan Ecosystem: nan Language: JavaScript Match: DOM: M (0/2)[] S (0/1)[] C (0/1)[] ECO: M (0/1)[] S (0/3)[] C (0/1)[] LING: M (0/2)[] S (1/1)[javascript] C (0/2)[] Collaboration:: 161-242: UNCOMMON 161-362: UNCOMMON 161-450: UNCOMMON
C17: P3-TEAM4 | D17: Dev362 | E17: Dev354 | F17: Dev495 | G17: Dev458 | H17: 3 | I17: DOM M(0/2)[] S(1/1)[web] C(0/1)[] | ECO M(0/1)[] S(1/3)[react] C(0/1)[] | LING M(0/2)[] S(1/1)[javascript] C(1/2)[java] | J17: =IFERROR(__xludf.DUMMYFUNCTION("IFERROR(REGEXEXTRACT($I17,""DOM\s*M\((\d+/\d+)\)""),"""") "),"0/2") -> 0/2 | K17: =IFERROR(__xludf.DUMMYFUNCTION("IFERROR(REGEXEXTRACT($I17,""DOM.*?S\((\d+/\d+)\)""),"""") "),"1/1") -> 1/1 | L17: =IFERROR(__xludf.DUMMYFUNCTION("IFERROR(REGEXEXTRACT($I17,""DOM.*?C\((\d+/\d+)\)""),"""") "),"0/1") -> 0/1 | M17: =IFERROR(__xludf.DUMMYFUNCTION("IFERROR(REGEXEXTRACT($I17,""ECO\s*M\((\d+/\d+)\)""),"""") "),"0/1") -> 0/1 | N17: =IFERROR(__xludf.DUMMYFUNCTION("IFERROR(REGEXEXTRACT($I17,""ECO.*?S\((\d+/\d+)\)""),"""") "),"1/3") -> 1/3 | O17: =IFERROR(__xludf.DUMMYFUNCTION("IFERROR(REGEXEXTRACT($I17,""ECO.*?C\((\d+/\d+)\)""),"""") "),"0/1") -> 0/1 | P17: =IFERROR(__xludf.DUMMYFUNCTION("IFERROR(REGEXEXTRACT($I17,""LING\s*M\((\d+/\d+)\)""),"""") "),"0/2") -> 0/2 | Q17: =IFERROR(__xludf.DUMMYFUNCTION("IFERROR(REGEXEXTRACT($I17,""LING.*?S\((\d+/\d+)\)""),"""") "),"1/1") -> 1/1 | R17: =IFERROR(__xludf.DUMMYFUNCTION("IFERROR(REGEXEXTRACT($I17,""LING[^|]*C\(([0-9]+/[0-9]+)\)""),"""") "),"1/2") -> 1/2 | S17: =IFERROR(__xludf.DUMMYFUNCTION("AND( VALUE(INDEX(SPLIT(J17,""/""),1))=VALUE(INDEX(SPLIT(J17,""/""),2)), VALUE(INDEX(SPLIT(M17,""/""),1))=VALUE(INDEX(SPLIT(M17,""/""),2)), VALUE(INDEX(SPLIT(P17,""/""),1))=VALUE(INDEX(SPLIT(P17,""/""),2)) ) "),FALSE) -> FALSE | T17: =IFERROR(__xludf.DUMMYFUNCTION(" (VALUE(INDEX(SPLIT(J17,""/""),2))-VALUE(INDEX(SPLIT(J17,""/""),1))) + (VALUE(INDEX(SPLIT(M17,""/""),2))-VALUE(INDEX(SPLIT(M17,""/""),1))) + (VALUE(INDEX(SPLIT(P17,""/""),2))-VALUE(INDEX(SPLIT(P17,""/""),1))) "),5.0) -> 5 | U17: Domain: Web Ecosystem: React Language: JavaScript Match: DOM: M (0/2)[] S (1/1)[web] C (0/1)[] ECO: M (0/1)[] S (1/3)[react] C (0/1)[] LING: M (0/2)[] S (1/1)[javascript] C (0/2)[] Collaboration:: 362-354: UNCOMMON 362-458: UNCOMMON 362-495: UNCOMMON | V17: Domain: Web Ecosystem: Node.js Language: JavaScript Match: DOM: M (0/2)[] S (1/1)[web] C (0/1)[] ECO: M (0/1)[] S (0/3)[] C (0/1)[] LING: M (0/2)[] S (1/1)[javascript] C (0/2)[] Collaboration:: 354-362: UNCOMMON 354-458: UNCOMMON 354-495: UNCOMMON | W17: Domain: Web Ecosystem: Spring Boot Language: Java Match: DOM: M (0/2)[] S (1/1)[web] C (0/1)[] ECO: M (0/1)[] S (0/3)[] C (0/1)[] LING: M (0/2)[] S (0/1)[] C (1/2)[java] Collaboration:: 495-354: UNCOMMON 495-362: UNCOMMON 495-458: UNCOMMON | X17: Domain: Mobile Ecosystem: iOS/iPadOS Language: Swift Match: DOM: M (0/2)[] S (0/1)[] C (0/1)[] ECO: M (0/1)[] S (0/3)[] C (0/1)[] LING: M (0/2)[] S (0/1)[] C (0/2)[] Collaboration:: 458-354: UNCOMMON 458-362: UNCOMMON 458-495: UNCOMMON
C18: P3-TEAM5 | D18: Dev439 | E18: Dev16 | F18: Dev209 | G18: Dev463 | H18: 5 | I18: DOM M(0/2)[] S(1/1)[web] C(0/1)[] | ECO M(0/1)[] S(1/3)[react] C(0/1)[] | LING M(0/2)[] S(1/1)[javascript] C(0/2)[] | J18: =IFERROR(__xludf.DUMMYFUNCTION("IFERROR(REGEXEXTRACT($I18,""DOM\s*M\((\d+/\d+)\)""),"""") "),"0/2") -> 0/2 | K18: =IFERROR(__xludf.DUMMYFUNCTION("IFERROR(REGEXEXTRACT($I18,""DOM.*?S\((\d+/\d+)\)""),"""") "),"1/1") -> 1/1 | L18: =IFERROR(__xludf.DUMMYFUNCTION("IFERROR(REGEXEXTRACT($I18,""DOM.*?C\((\d+/\d+)\)""),"""") "),"0/1") -> 0/1 | M18: =IFERROR(__xludf.DUMMYFUNCTION("IFERROR(REGEXEXTRACT($I18,""ECO\s*M\((\d+/\d+)\)""),"""") "),"0/1") -> 0/1 | N18: =IFERROR(__xludf.DUMMYFUNCTION("IFERROR(REGEXEXTRACT($I18,""ECO.*?S\((\d+/\d+)\)""),"""") "),"1/3") -> 1/3 | O18: =IFERROR(__xludf.DUMMYFUNCTION("IFERROR(REGEXEXTRACT($I18,""ECO.*?C\((\d+/\d+)\)""),"""") "),"0/1") -> 0/1 | P18: =IFERROR(__xludf.DUMMYFUNCTION("IFERROR(REGEXEXTRACT($I18,""LING\s*M\((\d+/\d+)\)""),"""") "),"0/2") -> 0/2 | Q18: =IFERROR(__xludf.DUMMYFUNCTION("IFERROR(REGEXEXTRACT($I18,""LING.*?S\((\d+/\d+)\)""),"""") "),"1/1") -> 1/1 | R18: =IFERROR(__xludf.DUMMYFUNCTION("IFERROR(REGEXEXTRACT($I18,""LING[^|]*C\(([0-9]+/[0-9]+)\)""),"""") "),"0/2") -> 0/2 | S18: =IFERROR(__xludf.DUMMYFUNCTION("AND( VALUE(INDEX(SPLIT(J18,""/""),1))=VALUE(INDEX(SPLIT(J18,""/""),2)), VALUE(INDEX(SPLIT(M18,""/""),1))=VALUE(INDEX(SPLIT(M18,""/""),2)), VALUE(INDEX(SPLIT(P18,""/""),1))=VALUE(INDEX(SPLIT(P18,""/""),2)) ) "),FALSE) -> FALSE | T18: =IFERROR(__xludf.DUMMYFUNCTION(" (VALUE(INDEX(SPLIT(J18,""/""),2))-VALUE(INDEX(SPLIT(J18,""/""),1))) + (VALUE(INDEX(SPLIT(M18,""/""),2))-VALUE(INDEX(SPLIT(M18,""/""),1))) + (VALUE(INDEX(SPLIT(P18,""/""),2))-VALUE(INDEX(SPLIT(P18,""/""),1))) "),5.0) -> 5 | U18: Domain: Web Ecosystem: React Language: JavaScript Match: DOM: M (0/2)[] S (1/1)[web] C (0/1)[] ECO: M (0/1)[] S (1/3)[react] C (0/1)[] LING: M (0/2)[] S (1/1)[javascript] C (0/2)[] Collaboration:: 439-16: UNCOMMON 439-209: UNCOMMON 439-463: UNCOMMON | V18: Domain: nan Ecosystem: iOS/iPadOS Language: nan Match: DOM: M (0/2)[] S (0/1)[] C (0/1)[] ECO: M (0/1)[] S (0/3)[] C (0/1)[] LING: M (0/2)[] S (0/1)[] C (0/2)[] Collaboration:: 16-209: UNCOMMON 16-439: UNCOMMON 16-463: UNCOMMON | W18: Domain: Web Ecosystem: Node.js Language: JavaScript Match: DOM: M (0/2)[] S (1/1)[web] C (0/1)[] ECO: M (0/1)[] S (0/3)[] C (0/1)[] LING: M (0/2)[] S (1/1)[javascript] C (0/2)[] Collaboration:: 209-16: UNCOMMON 209-439: UNCOMMON 209-463: UNCOMMON | X18: Domain: Web Ecosystem: Vue Language: JavaScript Match: DOM: M (0/2)[] S (1/1)[web] C (0/1)[] ECO: M (0/1)[] S (0/3)[] C (0/1)[] LING: M (0/2)[] S (1/1)[javascript] C (0/2)[] Collaboration:: 463-16: UNCOMMON 463-209: UNCOMMON 463-439: UNCOMMON
J19: =IFERROR(__xludf.DUMMYFUNCTION("IFERROR(REGEXEXTRACT($I19,""DOM\s*M\((\d+/\d+)\)""),"""") "),"") | K19: =IFERROR(__xludf.DUMMYFUNCTION("IFERROR(REGEXEXTRACT($I19,""DOM.*?S\((\d+/\d+)\)""),"""") "),"") | L19: =IFERROR(__xludf.DUMMYFUNCTION("IFERROR(REGEXEXTRACT($I19,""DOM.*?C\((\d+/\d+)\)""),"""") "),"") | M19: =IFERROR(__xludf.DUMMYFUNCTION("IFERROR(REGEXEXTRACT($I19,""ECO\s*M\((\d+/\d+)\)""),"""") "),"") | N19: =IFERROR(__xludf.DUMMYFUNCTION("IFERROR(REGEXEXTRACT($I19,""ECO.*?S\((\d+/\d+)\)""),"""") "),"") | O19: =IFERROR(__xludf.DUMMYFUNCTION("IFERROR(REGEXEXTRACT($I19,""ECO.*?C\((\d+/\d+)\)""),"""") "),"") | P19: =IFERROR(__xludf.DUMMYFUNCTION("IFERROR(REGEXEXTRACT($I19,""LING\s*M\((\d+/\d+)\)""),"""") "),"") | Q19: =IFERROR(__xludf.DUMMYFUNCTION("IFERROR(REGEXEXTRACT($I19,""LING.*?S\((\d+/\d+)\)""),"""") "),"") | R19: =IFERROR(__xludf.DUMMYFUNCTION("IFERROR(REGEXEXTRACT($I19,""LING[^|]*C\(([0-9]+/[0-9]+)\)""),"""") "),"")
